2019-05-16 21:32:42,687 INFO: Board Games startup [in C:\Users\jonat\Documents\GitHub\boardGamesPoll\app\__init__.py:45]
2019-05-16 21:40:28,213 INFO: Board Games startup [in C:\Users\jonat\Documents\GitHub\boardGamesPoll\app\__init__.py:45]
2019-05-16 21:40:34,673 ERROR: Exception on /login [POST] [in C:\Users\jonat\Anaconda3\lib\site-packages\flask\app.py:1761]
Traceback (most recent call last):
  File "C:\Users\jonat\Anaconda3\lib\site-packages\sqlalchemy\engine\base.py", line 1193, in _execute_context
    context)
  File "C:\Users\jonat\Anaconda3\lib\site-packages\sqlalchemy\engine\default.py", line 509, in do_execute
    cursor.execute(statement, parameters)
sqlite3.OperationalError: no such column: user.is_admin

The above exception was the direct cause of the following exception:

Traceback (most recent call last):
  File "C:\Users\jonat\Anaconda3\lib\site-packages\flask\app.py", line 2292, in wsgi_app
    response = self.full_dispatch_request()
  File "C:\Users\jonat\Anaconda3\lib\site-packages\flask\app.py", line 1815, in full_dispatch_request
    rv = self.handle_user_exception(e)
  File "C:\Users\jonat\Anaconda3\lib\site-packages\flask\app.py", line 1718, in handle_user_exception
    reraise(exc_type, exc_value, tb)
  File "C:\Users\jonat\Anaconda3\lib\site-packages\flask\_compat.py", line 35, in reraise
    raise value
  File "C:\Users\jonat\Anaconda3\lib\site-packages\flask\app.py", line 1813, in full_dispatch_request
    rv = self.dispatch_request()
  File "C:\Users\jonat\Anaconda3\lib\site-packages\flask\app.py", line 1799, in dispatch_request
    return self.view_functions[rule.endpoint](**req.view_args)
  File "C:\Users\jonat\Documents\GitHub\boardGamesPoll\app\routes.py", line 125, in login
    user = User.query.filter_by(username=form.username.data).first()
  File "C:\Users\jonat\Anaconda3\lib\site-packages\sqlalchemy\orm\query.py", line 2895, in first
    ret = list(self[0:1])
  File "C:\Users\jonat\Anaconda3\lib\site-packages\sqlalchemy\orm\query.py", line 2687, in __getitem__
    return list(res)
  File "C:\Users\jonat\Anaconda3\lib\site-packages\sqlalchemy\orm\query.py", line 2995, in __iter__
    return self._execute_and_instances(context)
  File "C:\Users\jonat\Anaconda3\lib\site-packages\sqlalchemy\orm\query.py", line 3018, in _execute_and_instances
    result = conn.execute(querycontext.statement, self._params)
  File "C:\Users\jonat\Anaconda3\lib\site-packages\sqlalchemy\engine\base.py", line 948, in execute
    return meth(self, multiparams, params)
  File "C:\Users\jonat\Anaconda3\lib\site-packages\sqlalchemy\sql\elements.py", line 269, in _execute_on_connection
    return connection._execute_clauseelement(self, multiparams, params)
  File "C:\Users\jonat\Anaconda3\lib\site-packages\sqlalchemy\engine\base.py", line 1060, in _execute_clauseelement
    compiled_sql, distilled_params
  File "C:\Users\jonat\Anaconda3\lib\site-packages\sqlalchemy\engine\base.py", line 1200, in _execute_context
    context)
  File "C:\Users\jonat\Anaconda3\lib\site-packages\sqlalchemy\engine\base.py", line 1413, in _handle_dbapi_exception
    exc_info
  File "C:\Users\jonat\Anaconda3\lib\site-packages\sqlalchemy\util\compat.py", line 265, in raise_from_cause
    reraise(type(exception), exception, tb=exc_tb, cause=cause)
  File "C:\Users\jonat\Anaconda3\lib\site-packages\sqlalchemy\util\compat.py", line 248, in reraise
    raise value.with_traceback(tb)
  File "C:\Users\jonat\Anaconda3\lib\site-packages\sqlalchemy\engine\base.py", line 1193, in _execute_context
    context)
  File "C:\Users\jonat\Anaconda3\lib\site-packages\sqlalchemy\engine\default.py", line 509, in do_execute
    cursor.execute(statement, parameters)
sqlalchemy.exc.OperationalError: (sqlite3.OperationalError) no such column: user.is_admin [SQL: 'SELECT user.id AS user_id, user.username AS user_username, user.email AS user_email, user.password_hash AS user_password_hash, user.about_me AS user_about_me, user.last_seen AS user_last_seen, user.is_admin AS user_is_admin \nFROM user \nWHERE user.username = ?\n LIMIT ? OFFSET ?'] [parameters: ('jonathan', 1, 0)] (Background on this error at: http://sqlalche.me/e/e3q8)
2019-05-16 21:41:05,783 INFO: Board Games startup [in C:\Users\jonat\Documents\GitHub\boardGamesPoll\app\__init__.py:45]
2019-05-16 21:41:08,222 INFO: Board Games startup [in C:\Users\jonat\Documents\GitHub\boardGamesPoll\app\__init__.py:45]
2019-05-16 21:42:23,828 INFO: Board Games startup [in C:\Users\jonat\Documents\GitHub\boardGamesPoll\app\__init__.py:45]
2019-05-16 21:44:13,938 INFO: Board Games startup [in C:\Users\jonat\Documents\GitHub\boardGamesPoll\app\__init__.py:45]
2019-05-16 21:53:35,836 INFO: Board Games startup [in C:\Users\jonat\Documents\GitHub\boardGamesPoll\app\__init__.py:45]
